Workbook

Sheet 0_説明
A1: SAP S/4HANA 日本語実習サイト — 付属の手順書（教材ドキュメント S4.docx に準拠）
A3: 本ワークブックはツールで自動生成しています（tools/make_cn_xlsx.py）。データはウェブサイトの HTML と同じソースから生成しているため、サイトと Excel の内容が食い違うことはありません。
A5: 【出典】教材ドキュメント S4.docx：425 ページ、6 大モジュール、222 タスク、埋め込み画像 1385 枚。
A6: 【サイト収録】画面参照 1369 件（重複除去後 1209 個の画像ファイル、20.7 MB）。サイズ 90×14 以下のアイコン/装飾画像 7 枚は除外しています。
A7: 【サイトのページ数】13 ページ：ホーム / 準備 / FI / CO / MM / PP / SD / T-code 早見表 / トラブルシューティング / タスク索引 / 講師用 / 受講者用 / 自習テスト
A9: 【重要説明 1｜画面】すべての画面は、原教材ドキュメントで著者が実際のシステムからキャプチャした中国語インターフェースのスクリーンショットであり、模式図ではなく、描き直しもしていません。
A10: 画面索引の各行には、原教材ドキュメントのファイル名（imageNNN.png）とサイト内パスを記載しているので、Word の原文と 1 枚ずつ照合できます。
A11: 【重要説明 2｜設定値】ドキュメント内のサンプル値（会社コード C999 / プラント F999 / 品目 R999-100 / 得意先 K001 など）は、原作者の教材環境に属します。
A12: 操作順序と設定ポイントはそのまま真似して構いませんが、番号と名称はご自分のシステムの値に置き換えてください。エラーメッセージもバージョン／言語／カスタマイズによって異なる場合があります。
A13: 【重要説明 3｜推測で補わない】標準値、項目一覧、テーブル名、SAP Note 番号が原教材ドキュメントに記載されていない場合、本ワークブックとサイトでは補いません。
A15: 【表ページの説明】
A16: 1_モジュール概要 ：6 モジュールのタスク数／ステップ数／画面数と主要 T-code
... A23: 8_進捗サマリ ：モジュール別に完了率を集計（数式で自動計算。7_学習WBS の判定を変更すると自動更新）

Sheet 1_モジュール概要
A1: モジュール | B1: ページファイル | C1: タスク数 | D1: 手順ステップ | E1: 画面数 | F1: IMG 設定／業務処理 | G1: 主要 T-code | H1: サイトのページ
A2: 準備作業 — システムへのログオンと IMG 設定への移動 | B2: prep.html | C2: 2 | D2: 5 | E2: 5 | F2: 0 / 0 | H2: prep.html
A3: 財務会計 FI（Financial Accounting） | B3: fi.html | C3: 45 | D3: 181 | E3: 304 | F3: 7 / 0 | G3: FS00、FB50、FB03、FS10N、FD01、FK01、FB70、FD10N、FB60、FK10N | H3: fi.html
A4: 管理会計 CO（Controlling） | B4: co.html | C4: 34 | D4: 126 | E4: 206 | F4: 3 / 1 | G4: OX19、OKEON、KA01、KA06、KL01、KP26、FB60、FB50、KB61、KK01、KB31N、KO04、KO88 | H4: co.html
A5: 品目管理 MM（Materials Management） | B5: mm.html | C5: 42 | D5: 168 | E5: 254 | F5: 24 / 8 | G5: MM60、MK01、ME11、MM02、FS00、MD03、MD04、ME51N、ME21N、MIGO、MIRO、MRBR、MMBE | H5: mm.html
A6: 生産計画 PP（Production Planning） | B6: pp.html | C6: 51 | D6: 220 | E6: 297 | F6: 8 / 17 | G6: CS01、CS15、CR11、CR01、KP26、CA01、CA02、PC01、CK11N、CK24、MM03、PP01、PP02、MM02、MD61、MD05、MD04、MD02 | H6: pp.html
A7: 販売管理 SD（Sales and Distribution） | B7: sd.html | C7: 48 | D7: 179 | E7: 303 | F7: 29 / 7 | G7: RVAA01、MM01、VK11、VD01、VD02、VA21、VL01N、VF01、VF02、VA05、MCTA、FS00、MIRO、CK11N、CK24、OBYC | H7: sd.html
A8: 合計 | B8: 13 ページ | C8: 222 | D8: 879 | E8: 1369 | G8: T-code の早見表は 4_T-code速查 をご覧ください | H8: index.html

Sheet 2_手順一覧
A1: モジュール | B1: No. | C1: タスク | D1: IMG/業務 | E1: T-code | F1: IMG パス（IMG 設定メニュー） | G1: 画面 | H1: 手順ステップ | I1: サイトリンク
A2: 準備 | B2: タスク 01 | C2: システムにログオン | G2: 3 | H2: 3 | I2: prep.html#t01
A3: 準備 | B3: タスク 02 | C3: IMG 設定へ進む | G3: 2 | H3: 2 | I3: prep.html#t02
A4: FI | B4: タスク 01 | C4: 会社コードを登録する | F4: エンタープライズ構造 → 定義 → 財務会計 → 会社コードの編集／コピー／削除／チェック、会社コードデータの編集 「会社コードデータの編集」を選択 | G4: 2 | H4: 2 | I4: fi.html#t01
A5: FI | B5: タスク 02 | C5: 勘定科目表を登録する | F5: 財務会計（新） → 総勘定元帳会計（新） → 総勘定元帳勘定 → マスタデータ → 総勘定元帳勘定-準備 → 勘定科目表一覧の編集。下図のとおりに登録し、登録が完了したら「保存」ボタンをクリックします。 | G5: 2 | H5: 2 | I5: fi.html#t02
A6: FI | B6: タスク 03 | C6: 会計年度バリアントを定義 | F6: 財務会計 → 財務会計のグローバル設定 → 会計年度 → 元帳 → 会計年度と転記期間 → 会計年度バリアントのメンテナンス（短縮会計年度のメンテナンス）「新規」ボタンをクリックして新規エントリ | G6: 2 | H6: 2 | I6: fi.html#t03
A7: FI | B7: タスク 04 | C7: 与信管理領域を登録 | F7: エンタープライズ構造 → 定義 → 財務会計 → 与信管理領域の定義。次の情報を登録します： | G7: 2 | H7: 2 | I7: fi.html#t04
A8: FI | B8: タスク 05 | C8: 会社コードのグローバルパラメータをメンテナンスする | F8: 財務会計 → 財務会計のグローバル設定 → 会社コード → グローバルパラメータの入力 | G8: 2 | H8: 2 | I8: fi.html#t05
A9: FI | B9: タスク 06 | C9: 勘定グループと入力制御を定義 | F9: 財務会計 → 総勘定元帳会計 → 総勘定元帳勘定 → マスタデータ → 準備 → 勘定グループの定義 | G9: 9 | H9: 9 | I9: fi.html#t06
A10: FI | B10: タスク 07 | C10: 項目ステータスバリアントを定義 | F10: 財務会計（新） → 財務会計のグローバル設定（新） → 項目 → 項目ステータスバリアントの定義 | G10: 19 | H10: 10 | I10: fi.html#t07
A11: FI | B11: タスク 08 | C11: 項目ステータスバリアントに会社コードを配賦 | F11: 財務会計 → 財務会計のグローバル設定 → 伝票 → 明細 → 管理会計 → 会社コードへの項目ステータスバリアントの割り当て | G11: 2 | H11: 2 | I11: fi.html#t08
A12: FI | B12: タスク 09 | C12: 留保利益勘定を定義 | F12: 財務会計（新） → 総勘定元帳会計（新） → マスタデータ → 総勘定元帳勘定 → 準備 → 留保利益勘定の定義 | G12: 7 | H12: 2 | I12: fi.html#t09
A13: FI | B13: タスク 10 | C13: 一般的な貸借対照表勘定を新規作成 | E13: FS00 | F13: 21710102 未払税金 → 付加価値税 → 売上税額 | G13: 2 | H13: 2 | I13: fi.html#t10
A14: FI | B14: タスク 11 | C14: 調整勘定－売掛金／買掛金を新規作成 | E14: FS00 | G14: 10 | H14: 3 | I14: fi.html#t11
A15: FI | B15: タスク 12 | C15: 材料購買勘定を新規登録する | E15: FS00 | G15: 3 | H15: 1 | I15: fi.html#t12
A16: FI | B16: タスク 13 | C16: 損益勘定を新規登録する | E16: FS00 | G16: 72 | H16: 36 | I16: fi.html#t13
A17: FI | B17: タスク 14 | C17: 勘定集計を照会 | G17: 1 | H17: 1 | I17: fi.html#t14
A18: FI | B18: タスク 15 | C18: 伝票番号範囲を会社コードにコピー | F18: 財務会計（新） → 財務会計のグローバル設定（新） → 伝票 → 伝票番号範囲 → 会社コードへのコピー | G18: 5 | H18: 4 | I18: fi.html#t15
A19: FI | B19: タスク 16 | C19: 転記期間バリアントを定義 | F19: 財務会計（新） → 財務会計のグローバル設定（新） → 元帳 → 会計年度と転記期間 → 転記期間-未消込転記期間バリアントの定義 | G19: 2 | H19: 1 | I19: fi.html#t16
A20: FI | B20: タスク 17 | C20: 転記期間バリアントを会社コードに配賦します | F20: 財務会計（新） → 財務会計のグローバル設定（新） → 元帳 → 会計年度と転記期間 → 転記期間-会社コードへのバリアント割当 | G20: 2 | H20: 1 | I20: fi.html#t17
A21: FI | B21: タスク 18 | C21: 転記期間を設定（業務処理） | F21: 会計 → 財務会計 → 総勘定元帳 → 環境 → 現行設定 → 未消込転記期間と締め済み転記期間 | G21: 4 | H21: 2 | I21: fi.html#t18
A22: FI | B22: タスク 19 | C22: 転記の許容範囲グループを定義 | F22: 財務会計（新） → 財務会計のグローバル設定（新） → 伝票 → 許容範囲グループ → 従業員の許容範囲グループの定義 | G22: 3 | H22: 2 | I22: fi.html#t19
A23: FI | B23: タスク 20 | C23: 総勘定元帳勘定の伝票を入力 | E23: FB50 FB03 | G23: 4 | H23: 4 | I23: fi.html#t20
A24: FI | B24: タスク 21 | C24: 総勘定元帳勘定残高を照会 | E24: FS10N | F24: IMG 設定 財務会計(新) → 財務会計のグローバル設定（新） → 販売税／仕入税 → 転記 → 税務勘定の定義 | G24: 11 | H24: 7 | I24: fi.html#t21
A25: FI | B25: タスク 22 | C25: 売掛金・買掛金の許容範囲グループを定義 | D25: IMG設定（カスタマイズ） | F25: 財務会計（新） → 売掛金・買掛金 → 業務取引 → 対外支払 → 支払 → 手動対外支払 → 許容範囲グループの定義 | G25: 3 | H25: 2 | I25: fi.html#t22
A26: FI | B26: タスク 23 | C26: 仕入先勘定グループを定義 | D26: IMG設定（カスタマイズ） | F26: 財務会計 → 売掛金・買掛金 → 仕入先勘定 → マスタデータ → 仕入先マスタ登録準備 → 画面フォーマット付きの勘定グループの定義（仕入先） | G26: 11 | H26: 8 | I26: fi.html#t23
A27: FI | B27: タスク 24 | C27: 仕入先勘定の番号範囲を定義 | D27: IMG設定（カスタマイズ） | F27: 財務会計 → 売掛金・買掛金 → 仕入先勘定 → マスタデータ → 仕入先マスタ登録準備 → 仕入先勘定の番号範囲の登録 | G27: 6 | H27: 5 | I27: fi.html#t24
A28: FI | B28: タスク 25 | C28: 仕入先の番号範囲を配賦 | D28: IMG設定（カスタマイズ） | F28: 財務会計 → 売掛金・買掛金 → 仕入先勘定 → マスタデータ → 仕入先マスタ登録準備 → 仕入先勘定グループへの番号範囲割当 | G28: 2 | H28: 1 | I28: fi.html#t25
A29: FI | B29: タスク 26 | C29: 得意先勘定グループを定義 | D29: IMG設定（カスタマイズ） | F29: 財務会計（新） → 売掛金・買掛金 → 得意先勘定 → マスタデータ → 得意先マスタ登録準備 → フォーマット付きの勘定グループの定義（得意先） | G29: 10 | H29: 8 | I29: fi.html#t26
A30: FI | B30: タスク 27 | C30: 得意先勘定の番号を定義 | D30: IMG設定（カスタマイズ） | F30: 財務会計（新） → 売掛金・買掛金 → 得意先勘定 → マスタデータ → 得意先マスタ登録準備 → 得意先勘定の番号範囲の登録 | G30: 5 | H30: 4 | I30: fi.html#t27
A31: FI | B31: タスク 28 | C31: 得意先の番号範囲を配賦 | F31: 財務会計（新） → 売掛金・買掛金 → 得意先勘定 → マスタデータ → 得意先マスタ登録準備 → 得意先勘定への番号範囲割当 | G31: 2 | H31: 1 | I31: fi.html#t28
A32: FI | B32: タスク 29 | C32: 受注先マスタを新規作成 | E32: FD01 | G32: 9 | H32: 4 | I32: fi.html#t29
A33: FI | B33: タスク 30 | C33: 入庫先マスタを新規作成 | E33: FD01 | G33: 0 | H33: 0 | I33: fi.html#t30
A34: FI | B34: タスク 31 | C34: 仕入先マスタを新規作成 | E34: FK01 | F34: 会計 → 財務会計 → 仕入先 → マスタレコード | G34: 6 | H34: 1 | I34: fi.html#t31
A35: FI | B35: タスク 32 | C35: 得意先請求書を入力 | E35: FB70 | G35: 3 | H35: 2 | I35: fi.html#t32
A36: FI | B36: タスク 33 | C36: 得意先から全額の入金を受領 | F36: 会計 → 財務会計 → 売掛金 → 伝票入力 → F-28 入金 | G36: 5 | H36: 4 | I36: fi.html#t33
A37: FI | B37: タスク 34 | C37: 得意先から一部の入金を受領 | E37: FB70 | G37: 7 | H37: 4 | I37: fi.html#t34
A38: FI | B38: タスク 35 | C38: 売掛金残高を照会 | F38: 会計 → 財務会計 → 売掛金 → 情報システム → 売掛金会計レポート → 得意先残高 → s_alr_87012172 | G38: 4 | H38: 1 | I38: fi.html#t35
A39: FI | B39: タスク 36 | C39: 得意先残高を照会 | E39: FD10N | F39: 会計 → 財務会計 → 売掛金 → 勘定 → FD10N | G39: 2 | H39: 2 | I39: fi.html#t36
A40: FI | B40: タスク 37 | C40: 仕入先請求書を受領 | E40: FB60 | F40: 会計 → 財務会計 → 買掛金 → 伝票入力 → FB60 請求書 | G40: 5 | H40: 1 | I40: fi.html#t37
...

Sheet 3_画面索引
A1: 画面# | B1: モジュール | C1: No. | D1: タスク | E1: 手順ステップ | F1: 原教材ドキュメントのファイル名 | G1: 幅 | H1: 高 | I1: KB | J1: サイト内パス
A2: 1 | B2: 準備 | C2: タスク 01 | D2: 登陆系统 | E2: 2 | F2: image2.png | G2: 590 | H2: 580 | I2: 11.4 | J2: assets/img/prep/t01/02_1_image2.png
A3: 2 | B3: 準備 | C3: タスク 01 | D3: 登陆系统 | E3: 3 | F3: image3.png | G3: 431 | H3: 309 | I3: 6.7 | J3: assets/img/prep/t01/03_1_image3.png
A4: 3 | B4: 準備 | C4: タスク 01 | D4: 登陆系统 | E4: 4 | F4: image4.png | G4: 727 | H4: 751 | I4: 14.1 | J4: assets/img/prep/t01/04_1_image4.png
A5: 4 | B5: 準備 | C5: タスク 02 | D5: 进入后台 | E5: 1 | F5: image5.png | G5: 587 | H5: 134 | I5: 4.9 | J5: assets/img/prep/t02/01_1_image5.png
A6: 5 | B6: 準備 | C6: タスク 02 | D6: 进入后台 | E6: 2 | F6: image6.png | G6: 539 | H6: 850 | I6: 29.7 | J6: assets/img/prep/t02/02_1_image6.png
A7: 6 | B7: FI | C7: タスク 01 | D7: 创建公司代码 | E7: 1 | F7: image7.png | G7: 394 | H7: 363 | I7: 11.9 | J7: assets/img/fi/t01/01_1_image7.png
A8: 7 | B8: FI | C8: タスク 01 | D8: 创建公司代码 | E8: 3 | F8: image9.png | G8: 348 | H8: 299 | I8: 5 | J8: assets/img/fi/t01/03_1_image9.png
A9: 8 | B9: FI | C9: タスク 02 | D9: 创建会计科目表 | E9: 1 | F9: image10.png | G9: 351 | H9: 412 | I9: 11.5 | J9: assets/img/fi/t02/01_1_image10.png
A10: 9 | B10: FI | C10: タスク 02 | D10: 创建会计科目表 | E10: 2 | F10: image11.png | G10: 600 | H10: 443 | I10: 9.1 | J10: assets/img/fi/t02/02_1_image11.png
A11: 10 | B11: FI | C11: タスク 03 | D11: 定义会计年度变式 | E11: 1 | F11: image12.png | G11: 452 | H11: 396 | I11: 13.4 | J11: assets/img/fi/t03/01_1_image12.png
A12: 11 | B12: FI | C12: タスク 03 | D12: 定义会计年度变式 | E12: 2 | F12: image13.png | G12: 798 | H12: 489 | I12: 22.5 | J12: assets/img/fi/t03/02_1_image13.png
A13: 12 | B13: FI | C13: タスク 04 | D13: 创建信贷控制范围 | E13: 1 | F13: image14.png | G13: 398 | H13: 439 | I13: 8 | J13: assets/img/fi/t04/01_1_image14.png
... A392: 391 | B392: CO | C392: タスク 07 | D392: 马老师学习笔记新建成本要素组 | E392: 5 | F392: image396.png | G392: 645 | H392: 675 | I392: 34.5 | J392: assets/img/co/t07/05_2_image396.png
A393: 392 | B393: CO | C393: タスク 09 | E393: 1 | F393: image398.png | G393: 398 | H393: 306 | I393: 6.7 | J393: assets/img/co/t09/01_1_image398.png
A394: 393 | B394: CO | C394: タスク 09 | E394: 1 | F394: image399.png | G394: 418 | H394: 303 | I394: 6.8 | J394: assets/img/co/t09/01_2_image399.png
A395: 394 | B395: CO | C395: タスク 09 | E395: 1 | F395: image400.png | G395: 404 | H395: 309 | I395: 6.8 | J395: assets/img/co/t09/01_3_image400.png
A396: 395 | B396: CO | C396: タスク 09 | E396: 1 | F396: image401.png | G396: 536 | H396: 523 | I396: 11.5 | J396: assets/img/co/t09/01_4_image401.png
A397: 396 | B397: CO | C397: タスク 10 | D397: 新建作业类型 | E397: 1 | F397: image403.png | G397: 304 | H397: 642 | I397: 13.4 | J397: assets/img/co/t10/01_1_image403.png
A398: 397 | B398: CO | C398: タスク 10 | D398: 新建作业类型 | E398: 1 | F398: image404.png | G398: 873 | H398: 703 | I398: 26.2 | J398: assets/img/co/t10/01_2_image404.png
A399: 398 | B399: CO | C399: タスク 10 | D399: 新建作业类型 | E399: 1 | F399: image407.png | G399: 652 | H399: 688 | I399: 17.4 | J399: assets/img/co/t10/01_3_image407.png
A400: 399 | B400: CO | C400: タスク 10 | D400: 新建作业类型 | E400: 1 | F400: image405.png | G400: 304 | H400: 642 | I400: 13.4 | J400: assets/img/co/t10/01_1_image403.png
A401: 400 | B401: CO | C401: タスク 10 | D401: 新建作业类型 | E401: 1 | F401: image406.png | G401: 873 | H401: 703 | I401: 26.2 | J401: assets/img/co/t10/01_2_image404.png
A402: 401 | B402: CO | C402: タスク 10 | D402: 新建作业类型 | E402: 2 | F402: image408.png | G402: 638 | H402: 688 | I402: 17.3 | J402: assets/img/co/t10/02_1_image408.png
A403: 402 | B403: CO | C403: タスク 11 | D403: 新建作业类型组 | E403: 1 | F403: image409.png | G403: 293 | H403: 595 | I403: 11.7 | J403: assets/img/co/t11/01_1_image409.png
A404: 403 | B404: CO | C404: タスク 11 | D404: 新建作业类型组 | E404: 1 | F404: image410.png | G404: 364 | H404: 244 | I404: 4.1 | J404: assets/img/co/t11/01_2_image410.png
A405: 404 | B405: CO | C405: タスク 11 | D405: 新建作业类型组 | E405: 2 | F405: image411.png | G405: 738 | H405: 193 | I405: 9.2 | J405: assets/img/co/t11/02_1_image411.png
A406: 405 | B406: CO | C406: タスク 12 | D406: 设置作业输出价格 | E406: 1 | F406: image412.png | G406: 324 | H406: 465 | I406: 11.6 | J406: assets/img/co/t12/01_1_image412.png
A407: 406 | B407: CO | C407: タスク 12 | D407: 设置作业输出价格 | E407: 2 | F407: image413.png | G407: 613 | H407: 818 | I407: 11.7 | J407: assets/img/co/t12/02_1_image413.png
A408: 407 | B408: CO | C408: タスク 12 | D408: 设置作业输出价格 | E408: 3 | F408: image414.png | G408: 933 | H408: 257 | I408: 9.9 | J408: assets/img/co/t12/03_1_image414.png
... A1370: 1369 | B1370: SD | C1370: タスク 48 | D1370: 运行资产负债表 | E1370: 25 | F1370: image1385.jpeg | G1370: 867 | H1370: 633 | I1370: 64.9 | J1370: assets/img/sd/t48/25_2_image1385.jpeg

Sheet 4_T-code早見表
A1: T-code | B1: 出題タスク数 | C1: モジュール | D1: 関連タスク
A2: FS00 | B2: 7 | C2: FI / MM / SD | D2: fi.html#t10（FI タスク 10 一般的な貸借対照表勘定を新規作成）；fi.html#t11（FI タスク 11 調整勘定－売掛金／買掛金を新規作成）；fi.html#t12（FI タスク 12 材料購買勘定を新規登録する）；fi.html#t13（FI タスク 13 損益勘定を新規登録する）；…など 7 か所
A3: MD04 | B3: 5 | C3: MM / PP | D3: mm.html#t35（MM タスク 35 在庫／所要量一覧を照会）；pp.html#t35（PP タスク 35 在庫／所要量一覧を照会）；pp.html#t37（PP タスク 37 計画手配を製造指図に変換）；pp.html#t39（PP タスク 39 購買依頼を購買発注に変換）；…など 5 か所
A4: CK24 | B4: 3 | C4: PP / SD | D4: pp.html#t23（PP タスク 23 価格のマーク）；pp.html#t25（PP タスク 25 価格をリリース）；sd.html#t48（SD タスク 48 貸借対照表を実行）
A5: FB50 | B5: 3 | C5: FI / CO | D5: fi.html#t20（FI タスク 20 総勘定元帳勘定の伝票を入力）；co.html#t15（CO タスク 15 一般費用の請求書を入力）；co.html#t32（CO タスク 32 内部指図の費用請求書を入力）
A6: MIGO | B6: 3 | C6: MM / PP | D6: mm.html#t38（MM タスク 38 購買の入庫を登録する）；pp.html#t40（PP タスク 40 購買発注に対して入庫）；pp.html#t45（PP タスク 45 製造指図に対して入庫）
A7: MIRO | B7: 3 | C7: MM / PP / SD | D7: mm.html#t39（MM タスク 39 購買請求書を入力する）；pp.html#t41（PP タスク 41 購買請求書を入力する）；sd.html#t48（SD タスク 48 貸借対照表を実行）
A8: CK11N | B8: 2 | C8: PP / SD | D8: pp.html#t22（PP タスク 22 製品原価見積を新規登録する）；sd.html#t48（SD タスク 48 貸借対照表を実行）
A9: CO02 | B9: 2 | C9: PP | D9: pp.html#t42（PP タスク 42 製造指図を指図発行）；pp.html#t47（PP タスク 47 製造指図を技術的完了にする）
A10: CR01 | B10: 2 | C10: PP | D10: pp.html#t12（PP タスク 12 人工工数タイプの作業区を新規作成）；pp.html#t13（PP タスク 13 機械工数タイプの作業区を新規作成）
A11: CR11 | B11: 2 | C11: PP | D11: pp.html#t10（PP タスク 10 人工工数の能力を新規作成）；pp.html#t11（PP タスク 11 機械工数の能力を新規作成）
A12: FB60 | B12: 2 | C12: FI / CO | D12: fi.html#t37（FI タスク 37 仕入先請求書を受領）；co.html#t14（CO タスク 14 費用の仕入先請求書を入力）
A13: FB70 | B13: 2 | C13: FI | D13: fi.html#t32（FI タスク 32 得意先請求書を入力）；fi.html#t34（FI タスク 34 得意先から一部の入金を受領）
... A65: VF02 | B65: 1 | C65: SD | D65: sd.html#t44（SD タスク 44 請求書をリリース）

Sheet 5_IMGパス一覧
A1: モジュール | B1: No. | C1: タスク | D1: IMG パス（IMG 設定メニュー）
A2: FI | B2: タスク 01 | C2: 会社コードを登録する | D2: エンタープライズ構造 → 定義 → 財務会計 → 会社コードの編集／コピー／削除／チェック、会社コードデータの編集 「会社コードデータの編集」を選択
A3: FI | B3: タスク 02 | C3: 勘定科目表を登録する | D3: 財務会計（新） → 総勘定元帳会計（新） → 総勘定元帳勘定 → マスタデータ → 総勘定元帳勘定-準備 → 勘定科目表一覧の編集。下図のとおりに登録し、登録が完了したら「保存」ボタンをクリックします。
A4: FI | B4: タスク 03 | C4: 会計年度バリアントを定義 | D4: 財務会計 → 財務会計のグローバル設定 → 会計年度 → 元帳 → 会計年度と転記期間 → 会計年度バリアントのメンテナンス（短縮会計年度のメンテナンス）「新規」ボタンをクリックして新規エントリ
A5: FI | B5: タスク 04 | C5: 与信管理領域を登録 | D5: エンタープライズ構造 → 定義 → 財務会計 → 与信管理領域の定義。次の情報を登録します：
A6: FI | B6: タスク 05 | C6: 会社コードのグローバルパラメータをメンテナンスする | D6: 財務会計 → 財務会計のグローバル設定 → 会社コード → グローバルパラメータの入力
A7: FI | B7: タスク 06 | C7: 勘定グループと入力制御を定義 | D7: 財務会計 → 総勘定元帳会計 → 総勘定元帳勘定 → マスタデータ → 準備 → 勘定グループの定義
A8: FI | B8: タスク 07 | C8: 項目ステータスバリアントを定義 | D8: 財務会計（新） → 財務会計のグローバル設定（新） → 項目 → 項目ステータスバリアントの定義
A9: FI | B9: タスク 08 | C9: 項目ステータスバリアントに会社コードを配賦 | D9: 財務会計 → 財務会計のグローバル設定 → 伝票 → 明細 → 管理会計 → 会社コードへの項目ステータスバリアントの割り当て
A10: FI | B10: タスク 09 | C10: 留保利益勘定を定義 | D10: 財務会計（新） → 総勘定元帳会計（新） → マスタデータ → 総勘定元帳勘定 → 準備 → 留保利益勘定の定義
A11: FI | B11: タスク 10 | C11: 一般的な貸借対照表勘定を新規作成 | D11: 21710102 未払税金 → 付加価値税 → 売上税額
A12: FI | B12: タスク 15 | C12: 伝票番号範囲を会社コードにコピー | D12: 財務会計（新） → 財務会計のグローバル設定（新） → 伝票 → 伝票番号範囲 → 会社コードへのコピー
... A204: SD | B204: タスク 48 | C204: 貸借対照表を実行 | D204: 会計 → 財務会計 → 総勘定元帳 → 情報システム → 総勘定元帳レポート → 貸借対照表／損益計算書／キャッシュフロー → 一般

Sheet 6_つまずきとエラー
A1: # | B1: 現象 / エラー | C1: 原因 | D1: 原教材ドキュメントが示す処理 | E1: 関連手順
A2: 1 | B2: 税コード J1 が無効です（メッセージ番号 FS217）。会社コード C999 の勘定 12010101 では売上税／仕入税に関する操作を実行できません | C2: 総勘定元帳勘定の「税タイプ」で、対応する売上税／仕入税の処理が許可されていない | D2: FS00 を実行 → 総勘定元帳勘定 12010101 を入力 → 「制御データ」で税分類を設定：「-」＝仕入税のみ許可、「+」＝売上税のみ許可、「*」＝すべての税分類を許可 → その後は得意先請求書／支払を正常に入力できます。なお、MIRO を終了してから入り直す必要があります（原教材ドキュメントの原文どおり） | E2: fi.html#t12（FI タスク 12 材料購買勘定を新規登録する）；fi.html#t13（FI タスク 13 損益勘定を新規登録する）；mm.html#t39（MM タスク 39 購買請求書を入力する）
A3: 2 | B3: 品目 R999-100「の強制勘定設定（勘定設定カテゴリの入力）」/ エントリ A999 BSX CN01 に対して勘定を決定できません | C3: 品目の会計ビューで「評価クラス」と自動記帳（OBYC / トランザクションコード BSX）の勘定決定が一致しない | D3: 登録済みの購買発注をすべて削除 → 品目の会計ビュー 1 の「評価クラス」を変更（原教材ドキュメントの例：原材料は 3000）→ 当期・前期・前年度の評価クラスもあわせてメンテナンスします。原教材ドキュメントでは、品目の登録（MM01）時に評価クラスを一度で正しく設定することを推奨しています | E3: mm.html#t21（MM タスク 21 評価クラスを定義する）；mm.html#t22（MM タスク 22 原材料（ROH）のマスタデータを新規登録する）；mm.html#t28（MM タスク 28 品目管理の自動記帳をメンテナンスする）
A4: 3 | B4: 自動記帳に関するエラー（入庫／請求書のときの勘定決定の失敗） | C4: 自動記帳ルール（OBYC）で該当するトランザクションキー／評価クラスの勘定がメンテナンスされていない | D4: 原教材の原文：「T-CODE OBYC で、次のようにメンテナンスするとこの問題を解決できます」（画面も添付） | E4: mm.html#t28（MM タスク 28 品目管理の自動記帳をメンテナンスする）；mm.html#t29（MM タスク 29 在庫勘定を自動記帳専用に設定する）
A5: 4 | B5: 品目 F999-100 は保管場所 P999 003 に存在しません | C5: 品目の「保管場所」ビューにその保管場所がない（またはその保管場所のマスタデータが登録されていない） | D5: MMSC でメンテナンスし（原教材の原文：「MMSC 维护」）、MM01/MM02 でその品目の該当する保管場所ビューが展開されていることを確認します | E5: mm.html#t02（MM タスク 02 保管場所を登録する）；mm.html#t24（MM タスク 24 完成品（FERT）のマスタデータを新規登録する）
A6: 5 | B6: VL01N で「選択した日付までの納入に対して期限の来た計画行がありません」とエラーが出る | C6: 納入伝票の登録時に使用する選択日付が、受注伝票の計画行（所要日付）と同じ期間に入っていない | D6: 原教材の原文：「解決策は、選択日付を伝票と一致させること」——VL01N の選択日付を伝票と同じに変更します | E6: sd.html#t42（SD タスク 42 出荷伝票（外向納入）を登録する）
A7: 6 | B7: VL01N で出荷伝票（外向納入）を登録できない | C7: 出庫できる在庫がない（教材のシナリオでは在庫が 0） | D7: 原教材の原文：「MB1C 501 で期首在庫を入力すると、VL01N の出荷伝票（外向納入）を作成できない問題を解決できます」 | E7: sd.html#t42（SD タスク 42 出荷伝票（外向納入）を登録する）；mm.html#t38（MM タスク 38 購買の入庫を登録する）
A8: 7 | B8: 内部作業 LAB 1001 の価格を決定できません（原価見積が作業価格を取得できない） | C8: その作業タイプには、当期の作業出力価格がメンテナンスされていない | D8: 原教材の原文：「CK11N で、次のように価格をメンテナンスすればよい」→ 価格をメンテナンスした後CK11N を終了し、その後、CK24 を再実行します | E8: pp.html#t12（PP タスク 12 作業出力価格を設定する）；pp.html#t22（PP タスク 22 製品原価見積を新規登録する）；pp.html#t23（PP タスク 23 価格のマーク）
A9: 8 | B9: 「原価センタに配賦できません。会計年度が有効化されていません」 | C9: 会社コードの会計年度／転記期間が有効化されていない（原価センタに転記できない） | D9: 原教材ドキュメントはこの見出しで本件の現象を記録し、画面を添付しています（対処方法の記述はありません）。FI 側のやり方に従うと：転記期間バリアントと期間のオープン/クローズ（関連タスクを参照）を確認し、会社コードの会計年度が有効化されていることを確かめてから転記します | E9: fi.html#t18（FI タスク 18 転記期間を設定（業務処理））；co.html#t01（CO タスク 01 管理会計領域を登録する）；co.html#t02（CO タスク 02 会社コードを管理会計領域に割り当てる）
A10: 9 | B10: 「カスタマイジングエラー：現在の業務取引グループではありません」 | C10: 原教材ドキュメントでは、SD モジュールの末尾にこのタイトルでカスタマイジングのエラーが記録されています（画面付き） | D10: 原教材ドキュメントには対処方法の記述がなく、画面のみが残されています。遭遇したときは、本ページ第 3 節の前提チェックリストと 1 項目ずつ照合して確認し、SPRO では「カスタマイジングエラー：現在の業務トランザクショングループではありません」をキーワードに特定してください | E10: sd.html#t48（SD タスク 48 貸借対照表を実行（原教材ドキュメントの最終章））
A11: 10 | B11: 製造指図／内部指図の決済で「エラーはなく、処理が完了しました」と出るのに結果が見えない | C11: これはエラーではありません。決済処理自体は成功しており、結果は決済結果やレポートで確認します | D11: 原教材ドキュメントの順序では、まず決済を実行し（KO88）、その後「内部指図の決済結果の照会」／「製造指図の原価レポートの照会」で確認します | E11: co.html#t33（CO タスク 33 内部指図の決済）；co.html#t34（CO タスク 34 内部指図の決済結果を照会する）；pp.html#t48（PP タスク 48 製造指図の差異決済）
A13: 問題が起きる前に確認する 6 項目（原教材ドキュメントのエラーから整理）
A14: • 転記期間がオープンになっているか、会計年度がアクティブになっているか（OB52 などの期間のオープン／クローズの設定は FI タスク 16〜18 を参照）。
A15: • 組織構造が正しく割り当てられているか：会社コード ↔ 管理会計領域、プラント ↔ 会社コード、購買組織 ↔ 会社コード/プラント、販売組織 ↔ 会社コード。
A16: • 品目マスタの会計ビューで正しい評価クラス（当期/前期/前年度）がメンテナンスされているか、また自動記帳 OBYC の勘定決定が完全かどうか。
A17: • 完成品の標準価格はすでに見積もられ、マーク/リリースされているか（CK11N → CK24）。そうでないと、製造指図の入庫時に価格を取得できません。
A18: • 在庫が存在するか（原教材ドキュメントでは複数の場面で MB1C 501 で期首在庫を入力したり、先に購買の入庫を行って在庫を補充したりしています）。
A19: • マスタデータがそろっているか：得意先（販売ビュー + パートナ）、品目（販売ビュー + 販売価格/条件レコード）、仕入先（購買データ/購買情報レコード）。

Sheet 7_学習WBS
A1: フェーズ | B1: No. | C1: タスク | D1: 完成基準（手順と画面） | E1: 画面数 | F1: 自己判定 | G1: 自分のシステムでの設定値 / 問題 | H1: サイトリンク
A2: 準備 | B2: タスク 01 | C2: システムにログオン | D2: SAP Client 側のアイコンは次のとおりです SAP Gui をダブルクリックすると、次の画面が表示されます： | E2: 3 | H2: prep.html#t01
A3: 準備 | B3: タスク 02 | C3: IMG 設定へ進む | D3: システムにログオンすると、次の画面のとおり トランザクションコードに spro を入力し、IMG 設定の画面に進みます | E3: 2 | H3: prep.html#t02
A4: FI | B4: タスク 01 | C4: 会社コードを登録する | D4: 解説：ここで 1 社の会社を登録し、登録したこの会社の業務を展開していきます。登録する会社は頤寧機械有限公司です。 会社コードは 1 つの完全な会計実体を表します。貸借対照表などがあります | E4: 2 | H4: fi.html#t01
A5: FI | B5: タスク 02 | C5: 勘定科目表を登録する | D5: 解説：勘定科目表の登録は、会計関連の設定で最も基礎となる作業です。異なる会社コードを異なる勘定科目表に割り当てることができ、関係は多対一です。パスは下図のとおりで、最初から設定を行います。 | E5: 2 | H5: fi.html#t02
A6: FI | B6: タスク 03 | C6: 会計年度バリアントを定義 | D6: 解説：会計年度バリアントは以降の財務処理で使用されます。会計年度バリアントは転記期間と特別期間の数を示し、つまりどの期間で転記するかを表します。 | E6: 2 | H6: fi.html#t03
A7: FI | B7: タスク 04 | C7: 与信管理領域を登録 | D7: 解説：与信管理領域は、信用管理を行う際に信用がどの範囲で有効になるかを管理するために使用します。これは SAP の販売管理と売掛金モジュールで信用リスクを管理するための組織構造です。会社コードと与信管理領域は多対一の関係… | E7: 2 | H7: fi.html#t04
A8: FI | B8: タスク 05 | C8: 会社コードのグローバルパラメータをメンテナンスする | D8: 解説：会社コードのグローバルパラメータは、会社の勘定科目表、与信管理領域、会計年度バリアントなどを設定するために使用します。主に会社コードのグローバルパラメータを入力し、上記の 3 つの組織構造を会社コードに割り当てます… | E8: 2 | H8: fi.html#t05
A9: FI | B9: タスク 06 | C9: 勘定グループと入力制御を定義 | D9: 解説：勘定グループの登録と入力制御、すなわち勘定を入力する際にどの項目が入力可能で、どの項目が非表示になるかなどに使用します。勘定グループは性質の似た勘定を分類するもので、主に業務処理で勘定マスタをメンテナンスします。（… | E9: 9 | H9: fi.html#t06
A10: FI | B10: タスク 07 | C10: 項目ステータスバリアントを定義 | D10: 解説：項目ステータスバリアントは会社コードに割り当てる重要なパラメータで、項目ステータスバリアントには多くの項目ステータスグループが列挙されています。項目ステータスグループは勘定科目の重要なパラメータであり、会計記帳伝票… | E10: 19 | H10: fi.html#t07
A11: FI | B11: タスク 08 | C11: 項目ステータスバリアントに会社コードを配賦 | D11: 解説：まず会社コードに配賦し、後で項目情報を勘定科目に配賦できます | E11: 2 | H11: fi.html#t08
A12: FI | B12: タスク 09 | C12: 留保利益勘定を定義 | D12: 財務会計（新）－総勘定元帳会計（新）－マスタデータ－総勘定元帳勘定－準備－留保利益勘定の定義 | E12: 7 | H12: fi.html#t09
A13: FI | B13: タスク 10 | C13: 一般的な貸借対照表勘定を新規作成 | D13: トランザクションコード：FS00 | E13: 2 | H13: fi.html#t10
... A56: CO | B56: タスク 08 | C56: 一次原価要素を変更 | D56: 原教材ドキュメントの画面に沿ってこのタスクを実施します（0 画面） | E56: 0 | H56: co.html#t08
A57: CO | B57: タスク 09 | D57: 原教材ドキュメントの画面に沿ってこのタスクを実施します（4 画面） | E57: 4 | H57: co.html#t09
A58: CO | B58: タスク 10 | C58: 作業タイプを新規作成 | D58: 会計－管理会計－原価センタ会計－マスタデータ－作業タイプ－個別処理－KL01-登録 | E58: 6 | H58: co.html#t10
A59: CO | B59: タスク 11 | C59: 作業タイプグループを新規作成 | D59: 「作業タイプ」ボタンをクリック | E59: 3 | H59: co.html#t11
A60: CO | B60: タスク 12 | C60: 作業出力価格を設定する | D60: 会計－管理会計－原価センタ会計－計画－作業出力/価格－KP26－変更 | E60: 7 | H60: co.html#t12
A61: CO | B61: タスク 13 | C61: 管理会計伝票の番号範囲をメンテナンス | D61: 管理会計－一般管理会計－組織構造－管理会計伝票の番号範囲のメンテナンス | E61: 6 | H61: co.html#t13
A62: CO | B62: タスク 14 | C62: 費用の仕入先請求書を入力 | D62: 解説：頤寧公司は佳音不動産公司から賃料の請求書を 1 通受け取りました。金額は 90000 で、ここではこの費用を 2001 財務部原価センタに計上する必要があります | E62: 3 | H62: co.html#t14
A63: CO | B63: タスク 15 | C63: 一般費用の請求書を入力 | D63: 解説：頤寧公司はさらに 25,500 元の電気料金を支払い、この電気料金は 2006 管理部の原価センタに記録されました。ここでは一般的な総勘定元帳伝票の方法でこの伝票を入力します。 | E63: 4 | H63: co.html#t15
A64: CO | B64: タスク 16 | C64: 原価センタレポートを実行 | D64: 会計－管理会計－原価センタ会計－情報システム－原価センタ会計のレポート－計画／実績比較－原価センタ：実績／計画／差異 | E64: 3 | H64: co.html#t16
A65: CO | B65: タスク 17 | C65: 原価センタデータの再転記 | D65: 解説：90,000 元の賃料が誤って 2001 財務部の原価センタに記録されました。会計伝票を逆仕訳する必要はありません。管理会計で「再転記」を行い、2006 管理部の原価センタに指定し直すだけです。 | E65: 6 | H65: co.html#t17
A66: CO | B66: タスク 18 | C66: 統計キー数値を新規作成 | D66: 解説：頤寧公司は、各原価センタの占有面積を使って賃料費用を配賦することにしました。SAP の管理会計では、占有面積のような非財務指標を「統計キー数値」で記録できます。ここでは賃料面積の統計キー数値を 1 つ登録します。 … | E66: 5 | H66: co.html#t18
A67: CO | B67: タスク 19 | C67: 統計キー数値の数量を入力 | D67: 会計－管理会計－原価センタ会計－実績記帳－統計キー数値－KB31N-入力 | E67: 3 | H67: co.html#t19
A68: CO | B68: タスク 20 | C68: 配賦サイクルを定義 | D68: 解説：頤寧公司が定めた賃料費用の配賦ルールは、2006 管理部原価センタに記録されたすべての賃料費用を、本社の各原価センタの占有面積に応じて各原価センタに配賦するというものです。製造部の勤務地はこのオフィス物件の中にない… | E68: 6 | H68: co.html#t20
A69: CO | B69: タスク 21 | C69: 配賦 | D69: 解説：前述の準備作業が完了したので、次に今月の月次締めで、賃料原価を各原価センタに配賦します 会計－管理会計－原価センタ会計－期末決算－単一機能－割当－KSV5 配賦 | E69: 3 | H69: co.html#t21
... A223: SD | B223: タスク 48 | C223: 貸借対照表を実行 | D223: 会計－財務会計－総勘定元帳－情報システム－総勘定元帳レポート－貸借対照表／損益計算書／キャッシュフロー－一般 | E223: 62 | H223: sd.html#t48

Sheet 8_進捗サマリ
A1: モジュール | B1: タスク数 | C1: ○ 完了 | D1: △ 進行中 | E1: × 未実施 | F1: 空白 | G1: 完成率 | H1: 画面数 | I1: 見積所要時間（分）
A2: 準備作業 — システムへのログオンと IMG 設定への移動 | B2: 2 | C2: =COUNTIF('7_学習WBS'!F2:F3,"○") | D2: =COUNTIF('7_学習WBS'!F2:F3,"△") | E2: =COUNTIF('7_学習WBS'!F2:F3,"×") | F2: =COUNTIF('7_学習WBS'!F2:F3,"") | G2: =IF(B2=0,0,C2/B2) | H2: 5 | I2: 50
A3: 財務会計 FI（Financial Accounting） | B3: 45 | C3: =COUNTIF('7_学習WBS'!F4:F48,"○") | D3: =COUNTIF('7_学習WBS'!F4:F48,"△") | E3: =COUNTIF('7_学習WBS'!F4:F48,"×") | F3: =COUNTIF('7_学習WBS'!F4:F48,"") | G3: =IF(B3=0,0,C3/B3) | H3: 304 | I3: 1125
A4: 管理会計 CO（Controlling） | B4: 34 | C4: =COUNTIF('7_学習WBS'!F49:F82,"○") | D4: =COUNTIF('7_学習WBS'!F49:F82,"△") | E4: =COUNTIF('7_学習WBS'!F49:F82,"×") | F4: =COUNTIF('7_学習WBS'!F49:F82,"") | G4: =IF(B4=0,0,C4/B4) | H4: 206 | I4: 850
A5: 品目管理 MM（Materials Management） | B5: 42 | C5: =COUNTIF('7_学習WBS'!F83:F124,"○") | D5: =COUNTIF('7_学習WBS'!F83:F124,"△") | E5: =COUNTIF('7_学習WBS'!F83:F124,"×") | F5: =COUNTIF('7_学習WBS'!F83:F124,"") | G5: =IF(B5=0,0,C5/B5) | H5: 254 | I5: 1050
A6: 生産計画 PP（Production Planning） | B6: 51 | C6: =COUNTIF('7_学習WBS'!F125:F175,"○") | D6: =COUNTIF('7_学習WBS'!F125:F175,"△") | E6: =COUNTIF('7_学習WBS'!F125:F175,"×") | F6: =COUNTIF('7_学習WBS'!F125:F175,"") | G6: =IF(B6=0,0,C6/B6) | H6: 297 | I6: 1275
A7: 販売管理 SD（Sales and Distribution） | B7: 48 | C7: =COUNTIF('7_学習WBS'!F176:F223,"○") | D7: =COUNTIF('7_学習WBS'!F176:F223,"△") | E7: =COUNTIF('7_学習WBS'!F176:F223,"×") | F7: =COUNTIF('7_学習WBS'!F176:F223,"") | G7: =IF(B7=0,0,C7/B7) | H7: 303 | I7: 1200
A8: 合計 | B8: =SUM(B2:B7) | C8: =SUM(C2:C7) | G8: =IF(B8=0,0,C8/B8)
A10: 説明：7_学習WBS の「自己判定」列で ○ / △ / × を選ぶと、本ページが自動集計します；所要時間の目安は 1 タスクあたり 25 分です（画面の確認と操作を含みます）。
